[2025-09-12 14:39:09] [INFO    ] discord.client: logging in using static token
[2025-09-12 14:39:10] [INFO    ] discord.gateway: Shard ID None has connected to Gateway (Session ID: 2e2d03170a89abf8d7338b0a474ac065).
[2025-09-12 14:40:00] [ERROR   ] discord.ext.commands.bot: Ignoring exception in command search
Traceback (most recent call last):
  File "C:\Users\Marcell Suyanto\OneDrive\Documents\GitHub\Discord_Agent\venv\Lib\site-packages\discord\ext\commands\core.py", line 266, in wrapped
    ret = await coro(*args, **kwargs)
          ^^^^^^^^^^^^^^^^^^^^^^^^^^^
  File "c:\Users\Marcell Suyanto\OneDrive\Documents\GitHub\Discord_Agent\src\discord_helper.py", line 54, in search
    response = search_text(query)
               ^^^^^^^^^^^^^^^^^^
  File "c:\Users\Marcell Suyanto\OneDrive\Documents\GitHub\Discord_Agent\src\langchain_helper.py", line 71, in search_text
    summary = wikipedia.summary(results[0], sentences=3)
              ^^^^^^^^^^^^^^^^^^^^^^^^^^^^^^^^^^^^^^^^^^
  File "C:\Users\Marcell Suyanto\OneDrive\Documents\GitHub\Discord_Agent\venv\Lib\site-packages\wikipedia\util.py", line 28, in __call__
    ret = self._cache[key] = self.fn(*args, **kwargs)
                             ^^^^^^^^^^^^^^^^^^^^^^^^
  File "C:\Users\Marcell Suyanto\OneDrive\Documents\GitHub\Discord_Agent\venv\Lib\site-packages\wikipedia\wikipedia.py", line 231, in summary
    page_info = page(title, auto_suggest=auto_suggest, redirect=redirect)
                ^^^^^^^^^^^^^^^^^^^^^^^^^^^^^^^^^^^^^^^^^^^^^^^^^^^^^^^^^
  File "C:\Users\Marcell Suyanto\OneDrive\Documents\GitHub\Discord_Agent\venv\Lib\site-packages\wikipedia\wikipedia.py", line 276, in page
    return WikipediaPage(title, redirect=redirect, preload=preload)
           ^^^^^^^^^^^^^^^^^^^^^^^^^^^^^^^^^^^^^^^^^^^^^^^^^^^^^^^^
  File "C:\Users\Marcell Suyanto\OneDrive\Documents\GitHub\Discord_Agent\venv\Lib\site-packages\wikipedia\wikipedia.py", line 299, in __init__
    self.__load(redirect=redirect, preload=preload)
  File "C:\Users\Marcell Suyanto\OneDrive\Documents\GitHub\Discord_Agent\venv\Lib\site-packages\wikipedia\wikipedia.py", line 345, in __load
    raise PageError(self.title)
wikipedia.exceptions.PageError: Page id "still road" does not match any pages. Try another id!

The above exception was the direct cause of the following exception:

Traceback (most recent call last):
  File "C:\Users\Marcell Suyanto\OneDrive\Documents\GitHub\Discord_Agent\venv\Lib\site-packages\discord\ext\commands\bot.py", line 1376, in invoke
    await ctx.command.invoke(ctx)
  File "C:\Users\Marcell Suyanto\OneDrive\Documents\GitHub\Discord_Agent\venv\Lib\site-packages\discord\ext\commands\core.py", line 1064, in invoke
    await injected(*ctx.args, **ctx.kwargs)  # type: ignore
    ^^^^^^^^^^^^^^^^^^^^^^^^^^^^^^^^^^^^^^^
  File "C:\Users\Marcell Suyanto\OneDrive\Documents\GitHub\Discord_Agent\venv\Lib\site-packages\discord\ext\commands\core.py", line 275, in wrapped
    raise CommandInvokeError(exc) from exc
discord.ext.commands.errors.CommandInvokeError: Command raised an exception: PageError: Page id "still road" does not match any pages. Try another id!
[2025-09-12 14:58:22] [WARNING ] discord.gateway: Shard ID None has stopped responding to the gateway. Closing and restarting.
[2025-09-12 14:58:22] [INFO    ] discord.gateway: Shard ID None session has been invalidated.
[2025-09-12 14:58:28] [INFO    ] discord.gateway: Shard ID None has connected to Gateway (Session ID: c7c08bf2035d70daf527284f326df5fc).
[2025-09-12 15:14:05] [INFO    ] discord.gateway: Shard ID None has successfully RESUMED session c7c08bf2035d70daf527284f326df5fc.
[2025-09-12 18:29:08] [ERROR   ] discord.client: Attempting a reconnect in 1.82s
Traceback (most recent call last):
  File "C:\Users\Marcell Suyanto\OneDrive\Documents\GitHub\Discord_Agent\venv\Lib\site-packages\aiohttp\connector.py", line 1532, in _create_direct_connection
    hosts = await self._resolve_host(host, port, traces=traces)
            ^^^^^^^^^^^^^^^^^^^^^^^^^^^^^^^^^^^^^^^^^^^^^^^^^^^
  File "C:\Users\Marcell Suyanto\OneDrive\Documents\GitHub\Discord_Agent\venv\Lib\site-packages\aiohttp\connector.py", line 1148, in _resolve_host
    return await asyncio.shield(resolved_host_task)
           ^^^^^^^^^^^^^^^^^^^^^^^^^^^^^^^^^^^^^^^^
  File "C:\Users\Marcell Suyanto\OneDrive\Documents\GitHub\Discord_Agent\venv\Lib\site-packages\aiohttp\connector.py", line 1179, in _resolve_host_with_throttle
    addrs = await self._resolver.resolve(host, port, family=self._family)
            ^^^^^^^^^^^^^^^^^^^^^^^^^^^^^^^^^^^^^^^^^^^^^^^^^^^^^^^^^^^^^
  File "C:\Users\Marcell Suyanto\OneDrive\Documents\GitHub\Discord_Agent\venv\Lib\site-packages\aiohttp\resolver.py", line 40, in resolve
    infos = await self._loop.getaddrinfo(
            ^^^^^^^^^^^^^^^^^^^^^^^^^^^^^
  File "C:\Program Files\WindowsApps\PythonSoftwareFoundation.Python.3.11_3.11.2544.0_x64__qbz5n2kfra8p0\Lib\asyncio\base_events.py", line 868, in getaddrinfo
    return await self.run_in_executor(
           ^^^^^^^^^^^^^^^^^^^^^^^^^^^
  File "C:\Program Files\WindowsApps\PythonSoftwareFoundation.Python.3.11_3.11.2544.0_x64__qbz5n2kfra8p0\Lib\concurrent\futures\thread.py", line 58, in run
    result = self.fn(*self.args, **self.kwargs)
             ^^^^^^^^^^^^^^^^^^^^^^^^^^^^^^^^^^
  File "C:\Program Files\WindowsApps\PythonSoftwareFoundation.Python.3.11_3.11.2544.0_x64__qbz5n2kfra8p0\Lib\socket.py", line 962, in getaddrinfo
    for res in _socket.getaddrinfo(host, port, family, type, proto, flags):
               ^^^^^^^^^^^^^^^^^^^^^^^^^^^^^^^^^^^^^^^^^^^^^^^^^^^^^^^^^^^
socket.gaierror: [Errno 11001] getaddrinfo failed

The above exception was the direct cause of the following exception:

Traceback (most recent call last):
  File "C:\Users\Marcell Suyanto\OneDrive\Documents\GitHub\Discord_Agent\venv\Lib\site-packages\discord\client.py", line 724, in connect
    self.ws = await asyncio.wait_for(coro, timeout=60.0)
              ^^^^^^^^^^^^^^^^^^^^^^^^^^^^^^^^^^^^^^^^^^
  File "C:\Program Files\WindowsApps\PythonSoftwareFoundation.Python.3.11_3.11.2544.0_x64__qbz5n2kfra8p0\Lib\asyncio\tasks.py", line 489, in wait_for
    return fut.result()
           ^^^^^^^^^^^^
  File "C:\Users\Marcell Suyanto\OneDrive\Documents\GitHub\Discord_Agent\venv\Lib\site-packages\discord\gateway.py", line 383, in from_client
    socket = await client.http.ws_connect(str(url))
             ^^^^^^^^^^^^^^^^^^^^^^^^^^^^^^^^^^^^^^
  File "C:\Users\Marcell Suyanto\OneDrive\Documents\GitHub\Discord_Agent\venv\Lib\site-packages\discord\http.py", line 566, in ws_connect
    return await self.__session.ws_connect(url, **kwargs)
           ^^^^^^^^^^^^^^^^^^^^^^^^^^^^^^^^^^^^^^^^^^^^^^
  File "C:\Users\Marcell Suyanto\OneDrive\Documents\GitHub\Discord_Agent\venv\Lib\site-packages\aiohttp\client.py", line 1067, in _ws_connect
    resp = await self.request(
           ^^^^^^^^^^^^^^^^^^^
  File "C:\Users\Marcell Suyanto\OneDrive\Documents\GitHub\Discord_Agent\venv\Lib\site-packages\aiohttp\client.py", line 770, in _request
    resp = await handler(req)
           ^^^^^^^^^^^^^^^^^^
  File "C:\Users\Marcell Suyanto\OneDrive\Documents\GitHub\Discord_Agent\venv\Lib\site-packages\aiohttp\client.py", line 725, in _connect_and_send_request
    conn = await self._connector.connect(
           ^^^^^^^^^^^^^^^^^^^^^^^^^^^^^^
  File "C:\Users\Marcell Suyanto\OneDrive\Documents\GitHub\Discord_Agent\venv\Lib\site-packages\aiohttp\connector.py", line 642, in connect
    proto = await self._create_connection(req, traces, timeout)
            ^^^^^^^^^^^^^^^^^^^^^^^^^^^^^^^^^^^^^^^^^^^^^^^^^^^
  File "C:\Users\Marcell Suyanto\OneDrive\Documents\GitHub\Discord_Agent\venv\Lib\site-packages\aiohttp\connector.py", line 1209, in _create_connection
    _, proto = await self._create_direct_connection(req, traces, timeout)
               ^^^^^^^^^^^^^^^^^^^^^^^^^^^^^^^^^^^^^^^^^^^^^^^^^^^^^^^^^^
  File "C:\Users\Marcell Suyanto\OneDrive\Documents\GitHub\Discord_Agent\venv\Lib\site-packages\aiohttp\connector.py", line 1538, in _create_direct_connection
    raise ClientConnectorDNSError(req.connection_key, exc) from exc
aiohttp.client_exceptions.ClientConnectorDNSError: Cannot connect to host gateway-us-east1-b.discord.gg:443 ssl:default [getaddrinfo failed]
[2025-09-12 18:29:11] [INFO    ] discord.gateway: Shard ID None session has been invalidated.
[2025-09-12 18:29:19] [INFO    ] discord.gateway: Shard ID None has connected to Gateway (Session ID: 10e9a6f4a1e14fdd65bd2f95b19f4c13).
[2025-09-12 18:30:30] [INFO    ] discord.gateway: Shard ID None has successfully RESUMED session 10e9a6f4a1e14fdd65bd2f95b19f4c13.
[2025-09-12 20:20:50] [INFO    ] discord.gateway: Shard ID None has successfully RESUMED session 10e9a6f4a1e14fdd65bd2f95b19f4c13.
[2025-09-12 21:08:04] [INFO    ] discord.gateway: Shard ID None has successfully RESUMED session 10e9a6f4a1e14fdd65bd2f95b19f4c13.
[2025-09-12 21:59:59] [INFO    ] discord.gateway: Shard ID None has successfully RESUMED session 10e9a6f4a1e14fdd65bd2f95b19f4c13.
[2025-09-12 22:47:12] [INFO    ] discord.gateway: Shard ID None has successfully RESUMED session 10e9a6f4a1e14fdd65bd2f95b19f4c13.
[2025-09-12 22:52:22] [INFO    ] discord.gateway: Shard ID None session has been invalidated.
